<?xml version="1.0"?>
<robot name="my_robot">

    <material name="grey">
        <color rgba="0.5 0.5 0.5 1" />
    </material>

    <material name="blue">
        <color rgba="0 0 0.5 1" />
    </material>

    <material name="orange">
        <color rgba="1 0.6 0 1" />
    </material>

    <material name="green">
        <color rgba="0 1 0.1 1" />
    </material>

    <material name="white">
        <color rgba="1 1 1 1" />
    </material>

    <material name="red">
        <color rgba="1 0 0 1" />
    </material>

    <material name="black">
        <color rgba="0 0 0 1" />
    </material>

    <link name="base_footprint"/>

    <joint name="base_joint" type="fixed">
        <parent link="base_footprint"/>
        <child link="base_link"/>
        <origin xyz="0 0 0.2" rpy="0 0 0"/>
    </joint>

    <link name="base_link">

        <visual>
            <geometry>
                <cylinder radius="0.35" length="0.2"/>
            </geometry>
            <origin xyz="0 0 0" rpy="0 0 0" />
            <material name="green"/>
        </visual>

        <visual>
            <geometry>
                <box size="0.05 0.5 0.1" />
            </geometry>
            <origin xyz="0.275 0 -0.1" rpy="0 0 0" />
            <material name="red"/>
        </visual>

        <collision>
            <geometry>
                <cylinder radius="0.35" length="0.2"/>
            </geometry>
        </collision>

        <inertial>
            <mass value="5.0"/>
            <inertia ixx="0.1" ixy="0" ixz="0" iyy="0.1" iyz="0" izz="0.1"/>
        </inertial>
    </link>

    <joint name="base_scan_joint" type="fixed">
        <parent link="base_link"/>
        <child link="base_scan"/>
        <origin xyz="0 0 0.13" rpy="0 0 0"/>
    </joint>

    <link name="base_scan">
        <visual>
            <geometry>
                <cylinder radius="0.1" length="0.06"/>
            </geometry>
            <origin xyz="0 0 0" rpy="0 0 0" />
            <material name="orange" />
        </visual>
    </link>

    <joint name="base_left_wheel_joint" type="continuous">
        <parent link="base_link"/>
        <child link="left_wheel"/>
        <origin xyz="-0.1 0.2 -0.1" rpy="0 0 0"/>
        <axis xyz="0 1 0"/>
    </joint>

    <link name="left_wheel">
        <visual>
            <geometry>
                <cylinder radius="0.1" length="0.05"/>
            </geometry>
            <origin xyz="0 0 0" rpy="1.57 0 0" />
            <material name="black" />
        </visual>
    </link>

    <joint name="base_right_wheel_joint" type="continuous">
        <parent link="base_link"/>
        <child link="right_wheel"/>
        <origin xyz="-0.1 -0.2 -0.1" rpy="0 0 0"/>
        <axis xyz="0 1 0"/>
    </joint>

    <link name="right_wheel">
        <visual>
            <geometry>
                <cylinder radius="0.1" length="0.05"/>
            </geometry>
            <origin xyz="0 0 0" rpy="1.57 0 0" />
            <material name="black" />
        </visual>
    </link>

    <joint name="base_caster_wheel_joint" type="revolute">
        <parent link="base_link"/>
        <child link="caster_wheel"/>
        <origin xyz="0.2 0 -0.15" rpy="0 0 0"/>
        <axis xyz="0 1 0"/>
        <limit lower="-3.14" upper="3.14" effort="0" velocity="10"/>
    </joint>

    <link name="caster_wheel">
        <visual>
            <geometry>
                <sphere radius="0.05"/>
            </geometry>
            <origin xyz="0 0 0" rpy="0 0 0" />
            <material name="grey" />
        </visual>

        <collision>
            <geometry>
                <sphere radius="0.05"/>
            </geometry>
        </collision>

        <!-- Inertial Properties for Caster Wheel (Example Values, Adjust as Needed) -->
        <inertial>
            <mass value="0.1"/>
            <inertia ixx="0.0001" ixy="0" ixz="0" iyy="0.0001" iyz="0" izz="0.0001"/>
        </inertial>
    </link>

</robot>
